2025-03-30 19:45:15,335 - ollama_agents - ERROR - Unexpected error: 2003 (HY000): Can't connect to MySQL server on 'localhost:3306' (10061)
2025-03-30 21:19:38,727 - ollama_agents - ERROR - Unexpected error: 2003 (HY000): Can't connect to MySQL server on 'localhost:3306' (10061)
2025-03-30 21:20:44,784 - ollama_agents - ERROR - Unexpected error: 2003 (HY000): Can't connect to MySQL server on 'localhost:3306' (10061)
2025-03-30 21:22:35,844 - ollama_agents - ERROR - Unexpected error: 2003 (HY000): Can't connect to MySQL server on 'localhost:3306' (10061)
2025-03-30 22:40:49,491 - ollama_agents - ERROR - Error gathering context: 'tuple' object has no attribute 'get'
2025-03-30 22:40:49,492 - ollama_agents - ERROR - Unexpected error in Pal agent: Failed to gather context: 'tuple' object has no attribute 'get'
Traceback (most recent call last):
  File "C:\Users\Acre-R\OneDrive - Acre Africa\Documents\Pal Chatbot\src\modules\context_management.py", line 21, in gather_context
    history_context = "\n".join([f"ðŸ‘¤ User: {h.get('prompt', '')}\nðŸ¤– {agent_name}: {h.get('response', '')}" for h in recent_history])
                                             ^^^^^
AttributeError: 'tuple' object has no attribute 'get'

During handling of the above exception, another exception occurred:

Traceback (most recent call last):
  File "C:\Users\Acre-R\OneDrive - Acre Africa\Documents\Pal Chatbot\src\agents\simple_agent.py", line 50, in run_agent
    self.context = gather_context(user_message, self.conversation_history, AGENT_NAME)
                   ^^^^^^^^^^^^^^^^^^^^^^^^^^^^^^^^^^^^^^^^^^^^^^^^^^^^^^^^^^^^^^^^^^^
  File "C:\Users\Acre-R\OneDrive - Acre Africa\Documents\Pal Chatbot\src\modules\context_management.py", line 30, in gather_context
    raise DataProcessingError(f"Failed to gather context: {str(e)}")
src.modules.errors.DataProcessingError: Failed to gather context: 'tuple' object has no attribute 'get'
2025-03-30 22:46:29,335 - ollama_agents - ERROR - Error gathering context: 'tuple' object has no attribute 'get'
2025-03-30 22:46:29,335 - ollama_agents - ERROR - Unexpected error in Pal agent: Failed to gather context: 'tuple' object has no attribute 'get'
Traceback (most recent call last):
  File "C:\Users\Acre-R\OneDrive - Acre Africa\Documents\Pal Chatbot\src\modules\context_management.py", line 21, in gather_context
    history_context = "\n".join([f"ðŸ‘¤ User: {h.get('prompt', '')}\nðŸ¤– {agent_name}: {h.get('response', '')}" for h in recent_history])
                                             ^^^^^
AttributeError: 'tuple' object has no attribute 'get'

During handling of the above exception, another exception occurred:

Traceback (most recent call last):
  File "C:\Users\Acre-R\OneDrive - Acre Africa\Documents\Pal Chatbot\src\agents\simple_agent.py", line 50, in run_agent
    self.context = gather_context(user_message, self.conversation_history, AGENT_NAME)
                   ^^^^^^^^^^^^^^^^^^^^^^^^^^^^^^^^^^^^^^^^^^^^^^^^^^^^^^^^^^^^^^^^^^^
  File "C:\Users\Acre-R\OneDrive - Acre Africa\Documents\Pal Chatbot\src\modules\context_management.py", line 30, in gather_context
    raise DataProcessingError(f"Failed to gather context: {str(e)}")
src.modules.errors.DataProcessingError: Failed to gather context: 'tuple' object has no attribute 'get'
2025-03-30 22:54:48,118 - ollama_agents - ERROR - Error gathering context: 'tuple' object has no attribute 'get'
2025-03-30 22:54:48,118 - ollama_agents - ERROR - Unexpected error in Pal agent: Failed to gather context: 'tuple' object has no attribute 'get'
Traceback (most recent call last):
  File "C:\Users\Acre-R\OneDrive - Acre Africa\Documents\Pal Chatbot\src\modules\context_management.py", line 21, in gather_context
    history_context = "\n".join([f"ðŸ‘¤ User: {h.get('prompt', '')}\nðŸ¤– {agent_name}: {h.get('response', '')}" for h in recent_history])
                                             ^^^^^
AttributeError: 'tuple' object has no attribute 'get'

During handling of the above exception, another exception occurred:

Traceback (most recent call last):
  File "C:\Users\Acre-R\OneDrive - Acre Africa\Documents\Pal Chatbot\src\agents\simple_agent.py", line 50, in run_agent
    self.context = gather_context(user_message, self.conversation_history, AGENT_NAME)
                   ^^^^^^^^^^^^^^^^^^^^^^^^^^^^^^^^^^^^^^^^^^^^^^^^^^^^^^^^^^^^^^^^^^^
  File "C:\Users\Acre-R\OneDrive - Acre Africa\Documents\Pal Chatbot\src\modules\context_management.py", line 30, in gather_context
    raise DataProcessingError(f"Failed to gather context: {str(e)}")
src.modules.errors.DataProcessingError: Failed to gather context: 'tuple' object has no attribute 'get'
2025-03-30 23:15:15,428 - ollama_agents - ERROR - Unexpected error: Only one live display may be active at once
2025-03-30 23:15:15,433 - ollama_agents - ERROR - Unexpected error: Only one live display may be active at once
